<?xml version="1.0"?>
<robot xmlns:xacro="http://www.ros.org/wiki/xacro" name="ammr">
  <!-- MACROS -->
  <!-- <xacro:include filename="macros.xacro"/> -->
  <!-- Global Material Definitions -->
  <material name="Gray">
    <color rgba="0.5 0.5 0.5 1.0"/>
  </material>
  <material name="Red">
    <color rgba="1 0 0 1.0"/>
  </material>
  <material name="Green">
    <color rgba="0 1 0 1.0"/>
  </material>
  <material name="Black">
    <color rgba="0 0 0 1.0"/>
  </material>
  <material name="Blue">
    <color rgba="0.2 0.2 0.8 1.0"/>
  </material>

  <!-- base_footprint-->
  <link name="base_footprint"/>

  <joint name="base_footprint_to_base_link" type="fixed">
    <parent link="base_footprint"/>
    <child link="base_link"/>
    <origin xyz="0.0 0.0 0.09" rpy="0 0 0"/>
  </joint>
   
  <!-- base_link (로봇 차체) -->
  <link name="base_link">
    <visual>
      <origin xyz="0 0 0.07" />
      <geometry>
        <box size="0.940 0.610 0.452"/>
      </geometry>
      <material name="Gray"/>
    </visual>
    <collision>
    <origin xyz="0 0 0.07" />
      <geometry>
        <box size="0.940 0.610 0.452"/>
      </geometry>
    </collision>
    <inertial>
      <mass value="20.0"/>
      <origin xyz="0 0 0.07" rpy="0 0 0"/>
      <inertia ixx="1.23" ixy="0" ixz="0" iyy="2.29" iyz="0" izz="3.18"/>
    </inertial>
  </link>

  <!-- base_scan (라이다 중심) -->
  <link name="base_scan">
  </link>

  <!-- base_scan 위치: base_link의 위 & 각 스캔 링크의 가운데 -->
  <joint name="base_link_to_base_scan" type="fixed">
    <parent link="base_link"/>
    <child link="base_scan"/>
    <origin xyz="0 0 0.216" rpy="0 0 0"/>
  </joint>

  <!-- base_scan_front (라이다 1) -->
  <link name="base_scan_front">
    <visual>
      <origin xyz="0 0 0.0218" rpy="0 0 0"/>
      <geometry>
        <cylinder radius="0.03" length="0.082"/>
      </geometry>
      <material name="Red"/>
    </visual>
    <collision>
      <geometry>
        <cylinder radius="0.03" length="0.082"/>
      </geometry>
    </collision>
    <inertial>
      <mass value="1.0"/>
      <origin xyz="0 0 0" rpy="0 0 0"/>
      <inertia ixx="0.00146" ixy="0" ixz="0" iyy="0.00146" iyz="0" izz="0.00125"/>
    </inertial>
  </link>
  <!-- base_scan_front 위치: base_link의 앞쪽 표면으로 돌출 -->
  <joint name="base_scan_to_base_scan_front" type="fixed">
    <parent link="base_scan"/>
    <child link="base_scan_front"/>
    <origin xyz="0.480 -0.315 0" rpy="3.14159 0 -0.7854"/>
  </joint>

  <!-- base_scan_rear (라이다 2) -->
  <link name="base_scan_rear">
    <visual>
      <origin xyz="0 0 0.0218" rpy="0 0 0"/>
      <geometry>
        <cylinder radius="0.03" length="0.082"/>
      </geometry>
      <material name="Red"/>
    </visual>
    <collision>
      <geometry>
        <cylinder radius="0.03" length="0.082"/>
      </geometry>
    </collision>
    <inertial>
      <mass value="1.0"/>
      <origin xyz="0 0 0" rpy="0 0 0"/>
      <inertia ixx="0.00146" ixy="0" ixz="0" iyy="0.00146" iyz="0" izz="0.00125"/>
    </inertial>
  </link>
  <!-- base_scan_rear 위치: base_link의 뒷쪽 표면으로 돌출 -->
  <joint name="base_scan_to_base_scan_rear" type="fixed">
    <parent link="base_scan"/>
    <child link="base_scan_rear"/>
    <origin xyz="-0.480 0.315 0" rpy="3.14159 0 2.35619"/>
  </joint>

  <material name="camera_mat">
        <color rgba="0.25 0.25 0.25 0.99"/>
  </material>

  <!-- Front Center Camera for Docking Waypoint -->
  <link name="front_camera_waypoint_center"/>
  <joint name="front_camera_waypoint_joint" type="fixed">
    <parent link="base_link"/>
    <child link="front_camera_waypoint_center"/>
    <origin xyz="0.0 0 0.277" rpy="0 0 0" />
  </joint>

  <!-- camera_front -->
  <link name="front_camera_center">
    <visual>
      <origin xyz="0 0 -0.016" rpy="0 0 0"/>
      <geometry>
        <mesh filename="package://turtlebot3_gazebo/meshes/zedxm.stl" />
      </geometry>
      <material name="camera_mat" />
    </visual>
    <collision>
      <geometry>
        <mesh filename="package://turtlebot3_gazebo/meshes/zedxm.stl" />
      </geometry>
    </collision>
  </link>
  <joint name="front_camera_center_joint" type="fixed">
    <parent link="base_link"/>
    <child link="front_camera_center"/>
    <origin xyz="0.534 0 0.277" rpy="0 0 0" />
  </joint>

  <!-- Front's Left Camera -->
  <link name="front_camera_l_frame" />
  <joint name="front_camera_l_frame_joint" type="fixed">
    <parent link="front_camera_center"/>
    <child link="front_camera_l_frame"/>
    <origin xyz="-0.01 0.025 0" rpy="0 0 0" />
  </joint>

  <link name="front_camera_l_optical_frame"/>
  <joint name="front_camera_l_optical_frame_joint" type="fixed">
    <origin xyz="0 0 0" rpy="-1.5708 0.0 -1.5708"/>
    <parent link="front_camera_l_frame"/>
    <child link="front_camera_l_optical_frame"/>
  </joint>

  <!-- Front's Right Camera -->
  <link name="front_camera_r_frame" />
  <joint name="front_camera_r_frame_joint" type="fixed">
    <parent link="front_camera_center"/>
    <child link="front_camera_r_frame"/>
    <origin xyz="-0.01 -0.025 0" rpy="0 0 0" />
  </joint>

  <link name="front_camera_r_optical_frame"/>
  <joint name="front_camera_r_optical_frame_joint" type="fixed">
    <origin xyz="0 0 0" rpy="-1.5708 0.0 -1.5708"/>
    <parent link="front_camera_r_frame"/>
    <child link="front_camera_r_optical_frame"/>
  </joint>

  <!-- Rear Center Camera for Docking Waypoint -->
  <link name="rear_camera_waypoint_center"/>
  <joint name="rear_camera_waypoint_joint" type="fixed">
    <parent link="base_link"/>
    <child link="rear_camera_waypoint_center"/>
    <origin xyz="0.0 0 0.277" rpy="0 0 3.14159" />
  </joint>

  <!-- camera_rear -->
  <link name="rear_camera_center">
    <visual>
      <origin xyz="0 0 -0.016" rpy="0 0 0"/>
      <geometry>
        <mesh filename="package://turtlebot3_gazebo/meshes/zedxm.stl" />
      </geometry>
      <material name="camera_mat" />
    </visual>
    <collision>
      <geometry>
        <mesh filename="package://turtlebot3_gazebo/meshes/zedxm.stl" />
      </geometry>
    </collision>
  </link>
  <joint name="rear_camera_center_joint" type="fixed">
    <parent link="base_link"/>
    <child link="rear_camera_center"/>
    <origin xyz="-0.534 0 0.277" rpy="0 0 3.14159" />
  </joint>

  <!-- rear's Left Camera -->
  <link name="rear_camera_l_frame" />
  <joint name="rear_camera_l_frame_joint" type="fixed">
    <parent link="rear_camera_center"/>
    <child link="rear_camera_l_frame"/>
    <origin xyz="-0.01 0.025 0" rpy="0 0 0" />
  </joint>

  <link name="rear_camera_l_optical_frame"/>
  <joint name="rear_camera_l_optical_frame_joint" type="fixed">
    <origin xyz="0 0 0" rpy="-1.5708 0.0 -1.5708"/>
    <parent link="rear_camera_l_frame"/>
    <child link="rear_camera_l_optical_frame"/>
  </joint>

  <!-- rear's Right Camera -->
  <link name="rear_camera_r_frame" />
  <joint name="rear_camera_r_frame_joint" type="fixed">
    <parent link="rear_camera_center"/>
    <child link="rear_camera_r_frame"/>
    <origin xyz="-0.01 -0.025 0" rpy="0 0 0" />
  </joint>

  <link name="rear_camera_r_optical_frame"/>
  <joint name="rear_camera_r_optical_frame_joint" type="fixed">
    <origin xyz="0 0 0" rpy="-1.5708 0.0 -1.5708"/>
    <parent link="rear_camera_r_frame"/>
    <child link="rear_camera_r_optical_frame"/>
  </joint>

  <!-- camera_right -->
  <link name="right_camera_center">
    <visual>
      <origin xyz="0 0 -0.016" rpy="0 0 0"/>
      <geometry>
        <mesh filename="package://turtlebot3_gazebo/meshes/zedxm.stl" />
      </geometry>
      <material name="camera_mat" />
    </visual>
    <collision>
      <geometry>
        <mesh filename="package://turtlebot3_gazebo/meshes/zedxm.stl" />
      </geometry>
    </collision>
  </link>
  <joint name="right_camera_center_joint" type="fixed">
    <parent link="base_link"/>
    <child link="right_camera_center"/>
    <origin xyz="0 -0.369 0.277" rpy="0 0 -1.5708"/>
  </joint>

  <!-- right's Left Camera -->
  <link name="right_camera_l_frame" />
  <joint name="right_camera_l_frame_joint" type="fixed">
    <parent link="right_camera_center"/>
    <child link="right_camera_l_frame"/>
    <origin xyz="-0.01 0.025 0" rpy="0 0 0" />
  </joint>

  <link name="right_camera_l_optical_frame"/>
  <joint name="right_camera_l_optical_frame_joint" type="fixed">
    <origin xyz="0 0 0" rpy="-1.5708 0.0 -1.5708"/>
    <parent link="right_camera_l_frame"/>
    <child link="right_camera_l_optical_frame"/>
  </joint>

  <!-- right's Right Camera -->
  <link name="right_camera_r_frame" />
  <joint name="right_camera_r_frame_joint" type="fixed">
    <parent link="right_camera_center"/>
    <child link="right_camera_r_frame"/>
    <origin xyz="-0.01 -0.025 0" rpy="0 0 0" />
  </joint>

  <link name="right_camera_r_optical_frame"/>
  <joint name="right_camera_r_optical_frame_joint" type="fixed">
    <origin xyz="0 0 0" rpy="-1.5708 0.0 -1.5708"/>
    <parent link="right_camera_r_frame"/>
    <child link="right_camera_r_optical_frame"/>
  </joint>

  <!-- camera_left -->
  <link name="left_camera_center">
    <visual>
      <origin xyz="0 0 -0.016" rpy="0 0 0"/>
      <geometry>
        <mesh filename="package://turtlebot3_gazebo/meshes/zedxm.stl" />
      </geometry>
      <material name="camera_mat" />
    </visual>
    <collision>
      <geometry>
        <mesh filename="package://turtlebot3_gazebo/meshes/zedxm.stl" />
      </geometry>
    </collision>
  </link>
  <joint name="left_camera_center_joint" type="fixed">
    <parent link="base_link"/>
    <child link="left_camera_center"/>
    <origin xyz="0 0.369 0.277" rpy="0 0 1.5708"/>
  </joint>

  <!-- left's Left Camera -->
  <link name="left_camera_l_frame" />
  <joint name="left_camera_l_frame_joint" type="fixed">
    <parent link="left_camera_center"/>
    <child link="left_camera_l_frame"/>
    <origin xyz="-0.01 0.025 0" rpy="0 0 0" />
  </joint>

  <link name="left_camera_l_optical_frame"/>
  <joint name="left_camera_l_optical_frame_joint" type="fixed">
    <origin xyz="0 0 0" rpy="-1.5708 0.0 -1.5708"/>
    <parent link="left_camera_l_frame"/>
    <child link="left_camera_l_optical_frame"/>
  </joint>

  <!-- left's Right Camera -->
  <link name="left_camera_r_frame" />
  <joint name="left_camera_r_frame_joint" type="fixed">
    <parent link="left_camera_center"/>
    <child link="left_camera_r_frame"/>
    <origin xyz="-0.01 -0.025 0" rpy="0 0 0" />
  </joint>

  <link name="left_camera_r_optical_frame"/>
  <joint name="left_camera_r_optical_frame_joint" type="fixed">
    <origin xyz="0 0 0" rpy="-1.5708 0.0 -1.5708"/>
    <parent link="left_camera_r_frame"/>
    <child link="left_camera_r_optical_frame"/>
  </joint>

  <!-- wheel_left -->
  <link name="wheel_left">
    <visual>
      <geometry>
        <cylinder radius="0.09" length="0.05"/>
      </geometry>
      <material name="Black"/>
    </visual>
    <collision>
      <geometry>
        <cylinder radius="0.09" length="0.05"/>
      </geometry>
    </collision>
    <inertial>
      <mass value="1.0"/>
      <origin xyz="0 0 0" rpy="0 0 0"/>
      <inertia ixx="0.00223" ixy="0" ixz="0" iyy="0.00223" iyz="0" izz="0.00405"/>
    </inertial>
  </link>
  <!-- wheel_left 위치: base_link의 측면, 아래쪽 -->
  <joint name="wheel_left_joint" type="continuous">
    <parent link="base_link"/>
    <child link="wheel_left"/>
    <origin xyz="0 0.33 0.0" rpy="-1.5707963267949 0 0"/>
    <axis xyz="0 0 1"/>
    <limit lower="-3.14159" upper="3.14159" effort="100" velocity="1.0"/>
  </joint>

  <!-- wheel_right -->
  <link name="wheel_right">
    <visual>
      <geometry>
        <cylinder radius="0.09" length="0.05"/>
      </geometry>
      <material name="Black"/>
    </visual>
    <collision>
      <geometry>
        <cylinder radius="0.09" length="0.05"/>
      </geometry>
    </collision>
    <inertial>
      <mass value="1.0"/>
      <origin xyz="0 0 0" rpy="0 0 0"/>
      <inertia ixx="0.00223" ixy="0" ixz="0" iyy="0.00223" iyz="0" izz="0.00405"/>
    </inertial>
  </link>
  <!-- wheel_right 위치: base_link의 반대측, 아래쪽 -->
  <joint name="wheel_right_joint" type="continuous">
    <parent link="base_link"/>
    <child link="wheel_right"/>
    <origin xyz="0 -0.33 0.0" rpy="-1.5707963267949 0 0"/>
    <axis xyz="0 0 1"/>
    <limit lower="-3.14159" upper="3.14159" effort="100" velocity="1.0"/>
  </joint>

  <xacro:include filename="ammr_plugins.xacro"/>

</robot>
