<?xml version="1.0" encoding="utf-8"?>
<!-- This URDF was automatically created by SolidWorks to URDF Exporter! Originally created by Stephen Brawner (brawner@gmail.com) 
     Commit Version: 1.6.0-4-g7f85cfe  Build Version: 1.6.7995.38578
     For more information, please see http://wiki.ros.org/sw_urdf_exporter -->
<robot
  name="wheelchair_urdf_files">

   <!-- Base footprint link -->
  <link name="base_footprint"/>
  <!-- Base link -->
  <link name="base_link">
  </link>
  <joint name="base_link_link_joint" type="fixed">
    <parent link="base_footprint"/>
    <child link="base_link"/>
    <origin xyz="0 0 0.3"/>
  </joint>

  <link
    name="wheelchair_frame">
    <inertial>
      <origin
        xyz="1.1817E-05 0.40859 0.020281"
        rpy="0 0 -1.570796" />
      <mass
        value="10.789" />
      <inertia
        ixx="0.27943"
        ixy="-0.00070217"
        ixz="0.00021066"
        iyy="0.19234"
        iyz="-0.057278"
        izz="0.17355" />
    </inertial>
    <visual>
      <origin
        xyz="0 0 0"
        rpy="0 0 -1.570796" />
      <geometry>
        <mesh
          filename="package://robot_simulator/robots/wheelchair/meshes/wheelchair_frame_base_link.STL" />
      </geometry>
      <material
        name="">
        <color
          rgba="0.79216 0.81961 0.93333 1" />
      </material>
    </visual>
    <collision>
      <origin
        xyz="0 0 0"
        rpy="0 0 -1.570796" />
      <geometry>
        <mesh
          filename="package://robot_simulator/robots/wheelchair/meshes/wheelchair_frame_base_link.STL" />
      </geometry>
    </collision>
  </link>
  <joint name="base_visual_joint" type="fixed">
    <parent link="base_link"/>
    <child link="wheelchair_frame"/>
    <origin xyz="0.225 0 -0.3"/>
  </joint>

  <link
    name="wheel_r_link">
    <inertial>
      <origin
        xyz="0.0441080860241803 8.88178419700125E-16 -1.11022302462516E-16"
        rpy="0 1.570796 0" />
      <mass
        value="1.11785636496393" />
      <inertia
        ixx="0.078372627877303"
        ixy="-1.77125185792784E-18"
        ixz="-1.12761256085879E-19"
        iyy="0.039239966752717"
        iyz="-9.06282829751847E-18"
        izz="0.0392393599948009" />
    </inertial>
    <visual>
      <origin
        xyz="0 0 0"
        rpy="0 1.570796 0" />
      <geometry>
        <mesh
          filename="package://robot_simulator/robots/wheelchair/meshes/wheel_r_link.STL" />
      </geometry>
      <material
        name="">
        <color
          rgba="0.792156862745098 0.819607843137255 0.933333333333333 1" />
      </material>
    </visual>
    <collision>
      <origin
        xyz="0 0 0"
        rpy="0 1.570796 0" />
      <geometry>
        <mesh
          filename="package://robot_simulator/robots/wheelchair/meshes/wheel_r_link.STL" />
      </geometry>
    </collision>
  </link>
  <joint
    name="wheel_r_joint"
    type="continuous">
    <origin
      xyz="0 -0.29262 0"
      rpy="-1.5707963267949 0 0" />
    <parent
      link="base_link" />
    <child
      link="wheel_r_link" />
    <axis
      xyz="0 0 1" />
  </joint>
  <link
    name="wheel_l_link">
    <inertial>
      <origin
        xyz="0.0441080860241805 6.93889390390723E-16 -3.88578058618805E-16"
        rpy="0 -1.570796 0" />
      <mass
        value="1.11785636496392" />
      <inertia
        ixx="0.0783726278773029"
        ixy="4.91793463251921E-18"
        ixz="-7.53745916717816E-18"
        iyy="0.0392399667527169"
        iyz="-5.20417042793042E-18"
        izz="0.0392393599948008" />
    </inertial>
    <visual>
      <origin
        xyz="0 0 0"
        rpy="0 -1.570796 0" />
      <geometry>
        <mesh
          filename="package://robot_simulator/robots/wheelchair/meshes/wheel_l_link.STL" />
      </geometry>
      <material
        name="">
        <color
          rgba="0.792156862745098 0.819607843137255 0.933333333333333 1" />
      </material>
    </visual>
    <collision>
      <origin
        xyz="0 0 0"
        rpy="0 1.5707963267949 0" />
      <geometry>
        <mesh
          filename="package://robot_simulator/robots/wheelchair/meshes/wheel_l_link.STL" />
      </geometry>
    </collision>
  </link>
  <joint
    name="wheel_l_joint"
    type="continuous">
    <origin
      xyz="0 0.29262 0"
      rpy="-1.5707963267949 0 0" />
    <parent
      link="base_link" />
    <child
      link="wheel_l_link" />
    <axis
      xyz="0 0 1" />
  </joint>
  <link
    name="caster_r_link">
    <inertial>
      <origin
        xyz="-3.12130959967405E-09 0.104209264665427 -0.00638474453380211"
        rpy="0 0 0" />
      <mass
        value="0.0641233529446961" />
      <inertia
        ixx="0.000140602918586523"
        ixy="-5.25202674672285E-12"
        ixz="-1.35152351145188E-11"
        iyy="4.09045485721611E-05"
        iyz="-3.06339546822628E-05"
        izz="0.000150905412643739" />
    </inertial>
    <visual>
      <origin
        xyz="0 0 0"
        rpy="0 0 0" />
      <geometry>
        <mesh
          filename="package://robot_simulator/robots/wheelchair/meshes/caster_r_link.STL" />
      </geometry>
      <material
        name="">
        <color
          rgba="0.63921568627451 0.666666666666667 0.67843137254902 1" />
      </material>
    </visual>
    <collision>
      <origin
        xyz="0 0 0"
        rpy="0 0 0" />
      <geometry>
        <mesh
          filename="package://robot_simulator/robots/wheelchair/meshes/caster_r_link.STL" />
      </geometry>
    </collision>
  </link>
  <joint
    name="caster_r_joint"
    type="continuous">
    <origin
      xyz="0.45 -0.258 -0.21775"
      rpy="1.5707963267949 0 1.5707963267949" />
    <parent
      link="base_link" />
    <child
      link="caster_r_link" />
    <axis
      xyz="0 0 1" />
  </joint>
  <link
    name="caster_wheel_r_link">
    <inertial>
      <origin
        xyz="3.68871599931708E-13 0 -2.77555756156289E-17"
        rpy="0 0 0" />
      <mass
        value="0.290948648858615" />
      <inertia
        ixx="0.00171792777524043"
        ixy="-3.23807165023355E-19"
        ixz="8.43924817788307E-20"
        iyy="0.000880037934920853"
        iyz="0"
        izz="0.000880037934920853" />
    </inertial>
    <visual>
      <origin
        xyz="0 0 0"
        rpy="0 0 0" />
      <geometry>
        <mesh
          filename="package://robot_simulator/robots/wheelchair/meshes/caster_wheel_r_link.STL" />
      </geometry>
      <material
        name="">
        <color
          rgba="0.796078431372549 0.823529411764706 0.937254901960784 1" />
      </material>
    </visual>
    <collision>
      <origin
        xyz="0 0 0"
        rpy="0 0 0" />
      <geometry>
        <mesh
          filename="package://robot_simulator/robots/wheelchair/meshes/caster_wheel_r_link.STL" />
      </geometry>
    </collision>
  </link>
  <joint
    name="caster_wheel_r_joint"
    type="continuous">
    <origin
      xyz="0.0127 0 -0.0508"
      rpy="-1.3026 0 0" />
    <parent
      link="caster_r_link" />
    <child
      link="caster_wheel_r_link" />
    <axis
      xyz="0 1 0" />
  </joint>
  <link
    name="caster_l_link">
    <inertial>
      <origin
        xyz="-3.12130948865175E-09 0.104209264665427 -0.00638474453380217"
        rpy="0 0 0" />
      <mass
        value="0.0641233529446964" />
      <inertia
        ixx="0.000140602918586524"
        ixy="-5.25202644245156E-12"
        ixz="-1.35152350658555E-11"
        iyy="4.09045485721617E-05"
        iyz="-3.06339546822628E-05"
        izz="0.00015090541264374" />
    </inertial>
    <visual>
      <origin
        xyz="0 0 0"
        rpy="0 0 0" />
      <geometry>
        <mesh
          filename="package://robot_simulator/robots/wheelchair/meshes/caster_l_link.STL" />
      </geometry>
      <material
        name="">
        <color
          rgba="0.63921568627451 0.666666666666667 0.67843137254902 1" />
      </material>
    </visual>
    <collision>
      <origin
        xyz="0 0 0"
        rpy="0 0 0" />
      <geometry>
        <mesh
          filename="package://robot_simulator/robots/wheelchair/meshes/caster_l_link.STL" />
      </geometry>
    </collision>
  </link>
  <joint
    name="caster_l_joint"
    type="continuous">
    <origin
      xyz="0.45 0.258 -0.21775"
      rpy="1.5707963267949 0 1.5707963267949" />
    <parent
      link="base_link" />
    <child
      link="caster_l_link" />
    <axis
      xyz="0 0 1" />
  </joint>
  <link
    name="caster_wheel_l_link">
    <inertial>
      <origin
        xyz="3.6892711108294E-13 2.77555756156289E-17 0"
        rpy="0 0 0" />
      <mass
        value="0.290948648858614" />
      <inertia
        ixx="0.00171792777524043"
        ixy="-6.31694569321117E-20"
        ixz="-4.59796098378092E-21"
        iyy="0.000880037934920852"
        iyz="7.31551485743025E-20"
        izz="0.000880037934920853" />
    </inertial>
    <visual>
      <origin
        xyz="0 0 0"
        rpy="0 0 0" />
      <geometry>
        <mesh
          filename="package://robot_simulator/robots/wheelchair/meshes/caster_wheel_l_link.STL" />
      </geometry>
      <material
        name="">
        <color
          rgba="0.796078431372549 0.823529411764706 0.937254901960784 1" />
      </material>
    </visual>
    <collision>
      <origin
        xyz="0 0 0"
        rpy="0 0 0" />
      <geometry>
        <mesh
          filename="package://robot_simulator/robots/wheelchair/meshes/caster_wheel_l_link.STL" />
      </geometry>
    </collision>
  </link>
  <joint
    name="caster_wheel_l_joint"
    type="continuous">
    <origin
      xyz="0.0127 0 -0.0508"
      rpy="0 0 0" />
    <parent
      link="caster_l_link" />
    <child
      link="caster_wheel_l_link" />
    <axis
      xyz="0 0 1" />
  </joint>

  <link name="base_scan"/>
  <joint
    name="base_scan_joint"
    type="fixed">
    <origin
      xyz="0.56908 0 0.0404"
      rpy="0 0 0" />
    <parent
      link="base_link" />
    <child
      link="base_scan" />
    <axis
      xyz="0 0 0" />
  </joint>

  <link
    name="lidar_r_link">
    <inertial>
      <origin
        xyz="0.00413164914455055 0.0155221181513021 0.00959210929655163"
        rpy="3.141592 0 -3.141592" />
      <mass
        value="0.0554197869782733" />
      <inertia
        ixx="2.47565352435023E-05"
        ixy="9.4643144062333E-08"
        ixz="3.54203416219165E-08"
        iyy="2.39394306809895E-05"
        iyz="-4.9424150019629E-08"
        izz="3.51059139511368E-05" />
    </inertial>
    <visual>
      <origin
        xyz="0 0 0"
        rpy="3.141592 0 -3.141592" />
      <geometry>
        <mesh
          filename="package://robot_simulator/robots/wheelchair/meshes/lidar_r_link.STL" />
      </geometry>
      <material
        name="">
        <color
          rgba="0.294117647058824 0.294117647058824 0.294117647058824 1" />
      </material>
    </visual>
    <collision>
      <origin
        xyz="0 0 0"
        rpy="3.141592 0 -3.141592" />
      <geometry>
        <mesh
          filename="package://robot_simulator/robots/wheelchair/meshes/lidar_r_link.STL" />
      </geometry>
    </collision>
  </link>
  <joint
    name="lidar_r_joint"
    type="fixed">
    <origin
      xyz="0 -0.28197 0"
      rpy="0 0 0" />
    <parent
      link="base_scan" />
    <child
      link="lidar_r_link" />
    <axis
      xyz="0 0 0" />
  </joint>
  <link
    name="lidar_l_link">
    <inertial>
      <origin
        xyz="0.00413164915732184 0.0155221181335719 0.00959210929427334"
        rpy="3.141592 0 -3.141592" />
      <mass
        value="0.0554197870193369" />
      <inertia
        ixx="2.47565352589425E-05"
        ixy="9.4643157361143E-08"
        ixz="3.54203516513508E-08"
        iyy="2.39394307035444E-05"
        iyz="-4.94241572710647E-08"
        izz="3.51059139791084E-05" />
    </inertial>
    <visual>
      <origin
        xyz="0 0 0"
        rpy="3.141592 0 -3.141592" />
      <geometry>
        <mesh
          filename="package://robot_simulator/robots/wheelchair/meshes/lidar_l_link.STL" />
      </geometry>
      <material
        name="">
        <color
          rgba="0.294117647058824 0.294117647058824 0.294117647058824 1" />
      </material>
    </visual>
    <collision>
      <origin
        xyz="0 0 0"
        rpy="3.141592 0 -3.141592" />
      <geometry>
        <mesh
          filename="package://robot_simulator/robots/wheelchair/meshes/lidar_l_link.STL" />
      </geometry>
    </collision>
  </link>
  <joint
    name="lidar_l_joint"
    type="fixed">
    <origin
      xyz="0 0.28197 0"
      rpy="0 0 0" />
    <parent
      link="base_scan" />
    <child
      link="lidar_l_link" />
    <axis
      xyz="0 0 0" />
  </joint>


  <link
    name="camera_r_link">
    <inertial>
      <origin
        xyz="0.000606179966556375 -0.00495007615976506 -0.00412138511006638"
        rpy="0 0 1.570796" />
      <mass
        value="0.0370266425386281" />
      <inertia
        ixx="8.87930504750657E-06"
        ixy="-1.64368854855412E-09"
        ixz="1.29020009778031E-09"
        iyy="1.8774304350479E-05"
        iyz="6.32850954173267E-07"
        izz="1.15826928491196E-05" />
    </inertial>
    <visual>
      <origin
        xyz="0 0 0"
        rpy="0 0 1.570796" />
      <geometry>
        <mesh
          filename="package://robot_simulator/robots/wheelchair/meshes/camera_r_link.STL" />
      </geometry>
      <material
        name="">
        <color
          rgba="0.792156862745098 0.819607843137255 0.933333333333333 1" />
      </material>
    </visual>
    <collision>
      <origin
        xyz="0 0 0"
        rpy="0 0 1.570796" />
      <geometry>
        <mesh
          filename="package://robot_simulator/robots/wheelchair/meshes/camera_r_link.STL" />
      </geometry>
    </collision>
  </link>
  <joint
    name="camera_r_joint"
    type="fixed">
    <origin
      xyz="0.56668 -0.28265 0.1248"
      rpy="0 0 0" />
    <parent
      link="base_link" />
    <child
      link="camera_r_link" />
    <axis
      xyz="0 0 0" />
  </joint>

<!-- SAVE -->
  <link name="camera_r_optical_link"/>
  <joint
    name="camera_r_optical_joint"
    type="fixed">
    <origin
      xyz="0.0 0.0 0.0"
      rpy="-1.570796 0 -1.570796" />
    <parent
      link="camera_r_link" />
    <child
      link="camera_r_optical_link" />
    <axis
      xyz="0 0 0" />
  </joint> 

  <link
    name="camera_l_link">
    <inertial>
      <origin
        xyz="0.00060618 -0.0049501 -0.0041214"
        rpy="0 0 1.570796" />
      <mass
        value="0.037027" />
      <inertia
        ixx="8.8793E-06"
        ixy="-1.6437E-09"
        ixz="1.2902E-09"
        iyy="1.8774E-05"
        iyz="6.3285E-07"
        izz="1.1583E-05" />
    </inertial>
    <visual>
      <origin
        xyz="0 0 0"
        rpy="0 0 1.570796" />
      <geometry>
        <mesh
          filename="package://robot_simulator/robots/wheelchair/meshes/camera_l_link.STL" />
      </geometry>
      <material
        name="">
        <color
          rgba="0.79216 0.81961 0.93333 1" />
      </material>
    </visual>
    <collision>
      <origin
        xyz="0 0 0"
        rpy="0 0 1.570796" />
      <geometry>
        <mesh
          filename="package://robot_simulator/robots/wheelchair/meshes/camera_l_link.STL" />
      </geometry>
    </collision>
  </link>
  <joint
    name="camera_l_joint"
    type="fixed">
    <origin
      xyz="0.56668 0.28135 0.1248"
      rpy="0.0 0 0" />
    <parent
      link="base_link" />
    <child
      link="camera_l_link" />
    <axis
      xyz="0 0 0" />
  </joint>

  <!-- SAVE -->
  <link name="camera_l_optical_link"/>
  <joint
    name="camera_l_optical_joint"
    type="fixed">
    <origin
      xyz="0.0 0.0 0.0"
      rpy="-1.570796 0 -1.570796" />
    <parent
      link="camera_l_link" />
    <child
      link="camera_l_optical_link" />
    <axis
      xyz="0 0 0" />
  </joint> 
</robot>